Workbook

Sheet 使用说明
A1: 理赔核算器(基于赔付科目表) 使用说明
A3: 一、这是事件已发生后的损失核算工具。逐条填写69个标准赔付科目的公式变量或凭证金额,自动得到各科目核定损失、15个大类小计与净核定合计。
A5: 二、颜色约定:黄底蓝字=输入格(只改这些);绿底=自动计算结果,请勿改动。
A6: 三、每行两种录入通道:①参数计算——填变量(如工时、费率、人数、单价),自动按计算式得数;②凭证直接核定——有合同/发票/账单总额时填"凭证直接核定金额"列,该列一经填写(>0)即覆盖参数计算,优先生效。
A7: 四、预填的参考值(黄底):响应费率1500元/h、镜像单价1250元/个、通知单价0.1元/人等来自网络资料行业参考区间,承保/核赔前应校准,后期获得真实数据可进行修改。
A8: 五、规则与汇总控制:
A9: 1. 营业中断测法二选一——S1带区行的"测法选择"下拉:公式外推法(启用S1-01/02)或财务对照法(启用S1-03),未选中口径自动记0,不可叠加。
A10: 2. 规则①SLA抵扣——在S1区末行填入已获SLA赔偿,汇总页自动从核定合计中扣减(以S1小计为上限)。
A11: 3. 和解协议整改费(R1-03)——须将"法律顾问已确认"选为"是"方计入。
A12: 4. 大类开关——汇总页每个大类一个ON/OFF开关(黄底):OFF时该大类计入金额记0、从合计与直/间分列中剔除,但科目明细与核定小计照常显示,便于按承保范围或分析口径切换。
A13: 六、示例数据:当前预填了一个勒索软件案例(取证、恢复、修补、通知、营业中断、赎金、云超额)作演示与自验。正式使用前,清空"科目核算表"中所有黄底输入格(保留参考值行可自行判断)及汇总页案件信息。
A14: 七、证据与前置条件:每行"提示"列给出关键执行要点;完整证据清单与执行要点见《赔付科目精简表》的"标准科目与测度公式"sheet,核赔时逐条对照。
... A16: 九、明细开关(承保过滤):科目核算表P列为每个明细科目提供ON/OFF。保险责任未覆盖的子项切OFF——该行核定损失照常计算显示(事实口径),但不进入汇总"计入金额"。橙色开关格提示该科目需特约/扩展/有限承保或可保性存疑,请对照保单逐项确认。大类开关(汇总页C列)与明细开关是两级与关系。

Sheet 科目核算表
A1: 编号 | B1: 标准科目 | C1: 计算式 | D1: 变量1标签 | E1: 值 | F1: 变量2标签 | G1: 值 | H1: 变量3标签 | I1: 值 | J1: 变量4标签 | K1: 值 | L1: 变量5标签 | M1: 值 | N1: 凭证直接核定金额(元,优先) | O1: 核定损失(元,自动) | P1: 计入?(承保过滤) | Q1: 计入金额(元,自动) | R1: 提示
A2: F1 事件响应与调查取证费(11项)
A3: F1-01 | B3: 外部事件响应与专家服务费 | C3: 工时 × 费率(参考800–3000元/h,默认1500可改) | D3: 响应/专家工时(h) | E3: 40 | F3: 费率(元/h) | G3: 1500 | O3: =IF(N3>0,N3,E3*G3) -> 60000 | P3: ON | Q3: =IF(P3="ON",O3,0) -> 60000 | R3: 工时须签到表佐证
A4: F1-02 | B4: 取证调查费 | C4: 工时 × 费率,或按取证机构发票 | D4: 取证工时(h) | E4: 60 | F4: 费率(元/h) | G4: 1200 | O4: =IF(N4>0,N4,E4*G4) -> 72000 | P4: ON | Q4: =IF(P4="ON",O4,0) -> 72000 | R4: Panel Vendor须事先书面同意
A5: F1-03 | B5: 取证镜像费 | C5: 镜像数量 × 单价(参考500–2000元/个,默认1250) | D5: 镜像数量(个) | E5: 10 | F5: 单价(元/个) | G5: 1250 | O5: =IF(N5>0,N5,E5*G5) -> 12500 | P5: ON | Q5: =IF(P5="ON",O5,0) -> 12500 | R5: 按镜像清单及验收单
A6: F1-04 | B6: 证据保全费 | C6: 保全机构发票核定 | O6: =IF(N6>0,N6,0) -> 0 | P6: ON | Q6: =IF(P6="ON",O6,0) -> 0 | R6: 附保全清单
A7: F1-05 | B7: 威胁狩猎费 | C7: 合同单价 × 服务时长 | D7: 服务时长(期) | F7: 期单价(元) | O7: =IF(N7>0,N7,E7*G7) -> 0 | P7: ON | Q7: =IF(P7="ON",O7,0) -> 0 | R7: 附交付报告
A8: F1-06 | B8: 供应链调查费 | C8: 第三方调查机构发票核定 | O8: =IF(N8>0,N8,0) -> 0 | P8: ON | Q8: =IF(P8="ON",O8,0) -> 0 | R8: 附供应商安全公告
A9: F1-07 | B9: 外部审计评估费 | C9: 审计机构合同金额核定 | O9: =IF(N9>0,N9,0) -> 0 | P9: ON | Q9: =IF(P9="ON",O9,0) -> 0 | R9: 附审计报告
A10: F1-08 | B10: 电子签名验证费 | C10: 验证机构发票核定 | O10: =IF(N10>0,N10,0) -> 0 | P10: ON | Q10: =IF(P10="ON",O10,0) -> 0 | R10: 来源场景※
A11: F1-09 | B11: 干扰源定位费 | C11: 检测机构发票核定 | O11: =IF(N11>0,N11,0) -> 0 | P11: ON | Q11: =IF(P11="ON",O11,0) -> 0 | R11: 限电磁干扰场景
A12: F1-10 | B12: 资金追回费 | C12: 追偿机构服务费发票核定 | O12: =IF(N12>0,N12,0) -> 0 | P12: ON | Q12: =IF(P12="ON",O12,0) -> 0 | R12: 仅服务费,被骗资金不在此
A13: F1-11 | B13: 临时工具采购费 | C13: 工具采购发票核定 | O13: =IF(N13>0,N13,0) -> 0 | P13: ON | Q13: =IF(P13="ON",O13,0) -> 0 | R13: 附用途说明
A14: F2 系统与数据恢复重建费(11项)
A15: F2-01 | B15: 系统恢复重建费 | C15: 恢复/重建工时 × 工程师费率 | D15: 工时(h) | E15: 200 | F15: 费率(元/h) | G15: 800 | O15: =IF(N15>0,N15,E15*G15) -> 160000 | P15: ON | Q15: =IF(P15="ON",O15,0) -> 160000 | R15: 违规场景须证非故意
A16: F2-02 | B16: 恶意组件清理费 | C16: 清理工时 × 费率 | D16: 工时(h) | E16: 40 | F16: 费率(元/h) | G16: 800 | O16: =IF(N16>0,N16,E16*G16) -> 32000 | P16: ON | Q16: =IF(P16="ON",O16,0) -> 32000 | R16: 附清理验收单
A17: F2-03 | B17: 数据恢复费 | C17: 恢复数据量 × 服务商单价 | D17: 恢复量(GB) | E17: 500 | F17: 单价(元/GB) | G17: 100 | O17: =IF(N17>0,N17,E17*G17) -> 50000 | P17: ON | Q17: =IF(P17="ON",O17,0) -> 50000 | R17: 恢复量以备份日志为准
A18: F2-04 | B18: 备份重建费 | C18: 备份重建工时 × 费率 | D18: 工时(h) | E18: 60 | F18: 费率(元/h) | G18: 800 | O18: =IF(N18>0,N18,E18*G18) -> 48000 | P18: ON | Q18: =IF(P18="ON",O18,0) -> 48000 | R18: 从运维记录提取
A19: F2-05 | B19: 数据迁移费 | C19: 迁移数据量 × 单价 | D19: 迁移量(GB) | F19: 单价(元/GB) | O19: =IF(N19>0,N19,E19*G19) -> 0 | P19: ON | Q19: =IF(P19="ON",O19,0) -> 0
A20: F2-06 | B20: 数据集清理费 | C20: 清理工时 × 费率 | D20: 工时(h) | F20: 费率(元/h) | O20: =IF(N20>0,N20,E20*G20) -> 0 | P20: ON | Q20: =IF(P20="ON",O20,0) -> 0 | R20: AI数据投毒场景
A21: F2-07 | B21: 网页与内容恢复费 | C21: 恢复/清理条目数 × 单价 | D21: 条目(页)数 | F21: 单价(元/条) | O21: =IF(N21>0,N21,E21*G21) -> 0 | P21: ON | Q21: =IF(P21="ON",O21,0) -> 0 | R21: 附篡改前后截图
A22: F2-08 | B22: 域名/DNS恢复费 | C22: 域名/DNS服务商账单核定 | O22: =IF(N22>0,N22,0) -> 0 | P22: ON | Q22: =IF(P22="ON",O22,0) -> 0 | R22: 附操作日志
A23: F2-09 | B23: 网络与配置恢复费 | C23: 工程师工时 × 费率 | D23: 工时(h) | F23: 费率(元/h) | O23: =IF(N23>0,N23,E23*G23) -> 0 | P23: ON | Q23: =IF(P23="ON",O23,0) -> 0
A24: F2-10 | B24: 抢修与安装费 | C24: 抢修/安装工时 × 费率 | D24: 工时(h) | F24: 费率(元/h) | O24: =IF(N24>0,N24,E24*G24) -> 0 | P24: ON | Q24: =IF(P24="ON",O24,0) -> 0
A25: F2-11 | B25: 环境清理费 | C25: 清理合同金额核定 | O25: =IF(N25>0,N25,0) -> 0 | P25: ON | Q25: =IF(P25="ON",O25,0) -> 0 | R25: 特约※,附灾害证明
A26: F3 整改加固与漏洞修复费(5项)
A27: F3-01 | B27: 漏洞修补费 | C27: (高危×4h+中危×2h+低危×1h) × 费率 × 加急系数(1.5–2,常规=1) | D27: 高危CVE数 | E27: 5 | F27: 中危CVE数 | G27: 10 | H27: 低危CVE数 | I27: 20 | J27: 费率(元/h) | K27: 800 | L27: 加急系数 | M27: 1.5 | O27: =IF(N27>0,N27,(E27*4+G27*2+I27*1)*K27*M27) -> 72000 | P27: ON | Q27: =IF(P27="ON",O27,0) -> 72000 | R27: 工时基准为行业假设,可校准
A28: F3-02 | B28: 系统与设施加固费 | C28: 加固/整改清单逐项核定(合同+验收总额) | O28: =IF(N28>0,N28,0) -> 0 | P28: ON | Q28: =IF(P28="ON",O28,0) -> 0 | R28: 仅事件驱动整改,预防性除外
A29: F3-03 | B29: 渗透测试费 | C29: 测试机构发票核定 | O29: =IF(N29>0,N29,0) -> 0 | P29: ON | Q29: =IF(P29="ON",O29,0) -> 0 | R29: 限整改验证
A30: F3-04 | B30: 事件后安全培训费 | C30: 参训人数 × 人均单价 | D30: 参训人数 | F30: 人均单价(元) | O30: =IF(N30>0,N30,E30*G30) -> 0 | P30: ON | Q30: =IF(P30="ON",O30,0) -> 0 | R30: 限事件后针对性培训
A31: F3-05 | B31: 商业秘密保护费 | C31: 保护措施合同金额核定 | O31: =IF(N31>0,N31,0) -> 0 | P31: ON | Q31: =IF(P31="ON",O31,0) -> 0 | R31: 扩展条款
A32: F4 法律与合规服务费(2项)
A33: F4-01 | B33: 律师服务费(非诉) | C33: 小时费率 × 工时(律师费账单) | D33: 工时(h) | F33: 小时费率(元) | O33: =IF(N33>0,N33,E33*G33) -> 0 | P33: ON | Q33: =IF(P33="ON",O33,0) -> 0 | R33: 附工时明细
A34: F4-02 | B34: 合规顾问费 | C34: 顾问合同金额核定 | O34: =IF(N34>0,N34,0) -> 0 | P34: ON | Q34: =IF(P34="ON",O34,0) -> 0
A35: F5 公关声誉与内容处置费(5项)
A36: F5-01 | B36: 公关服务费 | C36: 公关公司合同/发票核定 | O36: =IF(N36>0,N36,0) -> 0 | P36: ON | Q36: =IF(P36="ON",O36,0) -> 0 | R36: 紧急属性须合同注明
A37: F5-02 | B37: 品牌监测费 | C37: 监测机构合同金额核定 | O37: =IF(N37>0,N37,0) -> 0 | P37: ON | Q37: =IF(P37="ON",O37,0) -> 0
A38: F5-03 | B38: 平台下架费 | C38: 下架次数 × 平台单价 | D38: 下架次数 | F38: 单价(元/次) | O38: =IF(N38>0,N38,E38*G38) -> 0 | P38: ON | Q38: =IF(P38="ON",O38,0) -> 0 | R38: 按平台操作日志
A39: F5-04 | B39: 广告重投费 | C39: 重投投放量 × 单价(仅重投部分) | D39: 重投量 | F39: 单价(元) | O39: =IF(N39>0,N39,E39*G39) -> 0 | P39: ON | Q39: =IF(P39="ON",O39,0) -> 0 | R39: 账单须区分重投
A40: F5-05 | B40: 业务关系修复费 | C40: 修复活动合同金额核定 | O40: =IF(N40>0,N40,0) -> 0 | P40: ON | Q40: =IF(P40="ON",O40,0) -> 0
...

Sheet 汇总
A1: 理赔核算汇总
A3: 案件编号:
A4: 案件名称: | B4: 示例:某公司勒索软件事件(演示数据,使用前清空)
A5: 核算日期:
A7: 大类编号 | B7: 赔付大类 | C7: 开关 | D7: 核定损失小计(元) | E7: 计入金额(元) | F7: 已填科目数
A8: F1 | B8: 事件响应与调查取证费 | C8: ON | D8: =SUM(科目核算表!O3,科目核算表!O4,科目核算表!O5,科目核算表!O6,科目核算表!O7,科目核算表!O8,科目核算表!O9,科目核算表!O10,科目核算表!O11,科目核算表!O12,科目核算表!O13) -> 144500 | E8: =IF(C8="ON",SUM(科目核算表!Q3,科目核算表!Q4,科目核算表!Q5,科目核算表!Q6,科目核算表!Q7,科目核算表!Q8,科目核算表!Q9,科目核算表!Q10,科目核算表!Q11,科目核算表!Q12,科目核算表!Q13),0) -> 144500 | F8: =COUNTIF(科目核算表!O3:O13,">0") -> 3
A9: F2 | B9: 系统与数据恢复重建费 | C9: ON | D9: =SUM(科目核算表!O15,科目核算表!O16,科目核算表!O17,科目核算表!O18,科目核算表!O19,科目核算表!O20,科目核算表!O21,科目核算表!O22,科目核算表!O23,科目核算表!O24,科目核算表!O25) -> 290000 | E9: =IF(C9="ON",SUM(科目核算表!Q15,科目核算表!Q16,科目核算表!Q17,科目核算表!Q18,科目核算表!Q19,科目核算表!Q20,科目核算表!Q21,科目核算表!Q22,科目核算表!Q23,科目核算表!Q24,科目核算表!Q25),0) -> 290000 | F9: =COUNTIF(科目核算表!O15:O25,">0") -> 4
A10: F3 | B10: 整改加固与漏洞修复费 | C10: ON | D10: =SUM(科目核算表!O27,科目核算表!O28,科目核算表!O29,科目核算表!O30,科目核算表!O31) -> 72000 | E10: =IF(C10="ON",SUM(科目核算表!Q27,科目核算表!Q28,科目核算表!Q29,科目核算表!Q30,科目核算表!Q31),0) -> 72000 | F10: =COUNTIF(科目核算表!O27:O31,">0") -> 1
A11: F4 | B11: 法律与合规服务费 | C11: ON | D11: =SUM(科目核算表!O33,科目核算表!O34) -> 0 | E11: =IF(C11="ON",SUM(科目核算表!Q33,科目核算表!Q34),0) -> 0 | F11: =COUNTIF(科目核算表!O33:O34,">0") -> 0
A12: F5 | B12: 公关声誉与内容处置费 | C12: ON | D12: =SUM(科目核算表!O36,科目核算表!O37,科目核算表!O38,科目核算表!O39,科目核算表!O40) -> 0 | E12: =IF(C12="ON",SUM(科目核算表!Q36,科目核算表!Q37,科目核算表!Q38,科目核算表!Q39,科目核算表!Q40),0) -> 0 | F12: =COUNTIF(科目核算表!O36:O40,">0") -> 0
A13: F6 | B13: 通知与客户响应费 | C13: ON | D13: =SUM(科目核算表!O42,科目核算表!O43,科目核算表!O44,科目核算表!O45,科目核算表!O46) -> 10000 | E13: =IF(C13="ON",SUM(科目核算表!Q42,科目核算表!Q43,科目核算表!Q44,科目核算表!Q45,科目核算表!Q46),0) -> 10000 | F13: =COUNTIF(科目核算表!O42:O46,">0") -> 1
A14: F7 | B14: 临时替代与应急运营费 | C14: ON | D14: =SUM(科目核算表!O48,科目核算表!O49,科目核算表!O50,科目核算表!O51,科目核算表!O52,科目核算表!O53,科目核算表!O54) -> 0 | E14: =IF(C14="ON",SUM(科目核算表!Q48,科目核算表!Q49,科目核算表!Q50,科目核算表!Q51,科目核算表!Q52,科目核算表!Q53,科目核算表!Q54),0) -> 0 | F14: =COUNTIF(科目核算表!O48:O54,">0") -> 0
A15: F8 | B15: 品牌修复费(单列) | C15: ON | D15: =SUM(科目核算表!O56) -> 0 | E15: =IF(C15="ON",SUM(科目核算表!Q56),0) -> 0 | F15: =COUNTIF(科目核算表!O56:O56,">0") -> 0
A16: S1 | B16: 营业中断收入损失 | C16: ON | D16: =SUM(科目核算表!O58,科目核算表!O59,科目核算表!O60) -> 320000 | E16: =IF(C16="ON",SUM(科目核算表!Q58,科目核算表!Q59,科目核算表!Q60),0) -> 320000 | F16: =COUNTIF(科目核算表!O58:O60,">0") -> 1
A17: S2 | B17: 自有财产与资源损失 | C17: ON | D17: =SUM(科目核算表!O63,科目核算表!O64,科目核算表!O65,科目核算表!O66,科目核算表!O67) -> 40000 | E17: =IF(C17="ON",SUM(科目核算表!Q63,科目核算表!Q64,科目核算表!Q65,科目核算表!Q66,科目核算表!Q67),0) -> 40000 | F17: =COUNTIF(科目核算表!O63:O67,">0") -> 1
A18: S3 | B18: 赎金(单列) | C18: ON | D18: =SUM(科目核算表!O69) -> 800000 | E18: =IF(C18="ON",SUM(科目核算表!Q69),0) -> 800000 | F18: =COUNTIF(科目核算表!O69:O69,">0") -> 1
A19: S4 | B19: 内部人力与额外运营成本(有限) | C19: ON | D19: =SUM(科目核算表!O71,科目核算表!O72) -> 0 | E19: =IF(C19="ON",SUM(科目核算表!Q71,科目核算表!Q72),0) -> 0 | F19: =COUNTIF(科目核算表!O71:O72,">0") -> 0
A20: R1 | B20: 第三方赔偿与和解责任 | C20: ON | D20: =SUM(科目核算表!O74,科目核算表!O75,科目核算表!O76,科目核算表!O77,科目核算表!O78,科目核算表!O79) -> 0 | E20: =IF(C20="ON",SUM(科目核算表!Q74,科目核算表!Q75,科目核算表!Q76,科目核算表!Q77,科目核算表!Q78,科目核算表!Q79),0) -> 0 | F20: =COUNTIF(科目核算表!O74:O79,">0") -> 0
A21: R2 | B21: 抗辩与应诉费用 | C21: ON | D21: =SUM(科目核算表!O81,科目核算表!O82,科目核算表!O83) -> 0 | E21: =IF(C21="ON",SUM(科目核算表!Q81,科目核算表!Q82,科目核算表!Q83),0) -> 0 | F21: =COUNTIF(科目核算表!O81:O83,">0") -> 0
A22: R3 | B22: 支付卡与卡组织相关责任 | C22: ON | D22: =SUM(科目核算表!O85,科目核算表!O86) -> 0 | E22: =IF(C22="ON",SUM(科目核算表!Q85,科目核算表!Q86),0) -> 0 | F22: =COUNTIF(科目核算表!O85:O86,">0") -> 0
B23: 计入核定损失合计(仅开关ON的大类) | E23: =SUM(E8:E22) -> 1676500
B24: 减:规则① SLA已获赔偿抵扣(不超过S1计入小计) | E24: =-MIN(科目核算表!E61,E16) -> 0
B25: 净核定损失 | E25: =E23+E24 -> 1676500
B27: 其中:间接损失口径小计(F8-01+S1-03,随开关联动) | E27: =IF(C15="ON",科目核算表!Q56,0)+IF(C16="ON",科目核算表!Q60,0) -> 0
B28: 其中:直接损失口径小计 | E28: =E23-E27 -> 1676500
B29: 参考:事实口径核定总损失(全部科目,不受任何开关影响) | E29: =SUM(D8:D22) -> 1676500
B30: 注:两级开关——汇总页C列控制整个大类,科目核算表P列控制单个明细项;明细计入=两级均为ON。开关只影响"计入金额",D列小计与科目核算表"核定损失"列始终显示事实口径。橙色开关格=该科目承保标记含特约/扩展/有限/存疑/※,最可能与保单责任有出入,请逐项核对条款后决定ON/OFF。
